<?xml version="1.0"?>
<robot name="/home/polaris/catkin_ws/src/webots_ros/urdf/Robot.urdf" xmlns:xacro="http://ros.org/wiki/xacro">
  <link name="base_link">
    <visual>
      <origin xyz="0 0 0.19" rpy="0 0 0"/>
      <geometry>
        <box size="0.39 0.24 0.32"/>
      </geometry>
    </visual>
    <collision>
      <origin xyz="0 0 0.19" rpy="0 0 0"/>
      <geometry>
        <box size="0.39 0.24 0.32"/>
      </geometry>
    </collision>
  </link>


  <link name="touch sensor">
    <visual>
      <origin xyz="0 0 0.19" rpy="0 0 0"/>
      <geometry>
        <box size="0.43 0.34 0.32"/>
      </geometry>
    </visual>
    <collision>
      <origin xyz="0 0 0.19" rpy="0 0 0"/>
      <geometry>
        <box size="0.43 0.34 0.32"/>
      </geometry>
    </collision>
  </link>


  <joint name="base_link_touch sensor_joint" type="fixed">
    <parent link="base_link"/>
    <child link="touch sensor"/>
    <origin xyz="0 0 0" rpy="0 0 0"/>
  </joint>


  <link name="engine_speaker">
  </link>


  <joint name="base_link_engine_speaker_joint" type="fixed">
    <parent link="base_link"/>
    <child link="engine_speaker"/>
    <origin xyz="0.1 0 0" rpy="0 0 0"/>
  </joint>

  <joint name="right_front_wheel" type="continuous">
    <parent link="base_link"/>
    <child link="vehicle wheel(1)"/>
    <axis xyz="1 0 0"/>
    <limit effort="1e+08" velocity="29.8"/>
    <origin xyz="0.162 -0.15 0.05" rpy="0 0 1.5708"/>
  </joint>
  <link name="vehicle wheel(1)">
    <visual>
      <origin xyz="0 0 0" rpy="0 1.570796 0"/>
      <geometry>
        <cylinder radius="0.05" length="0.04"/>
      </geometry>
    </visual>
    <collision>
      <origin xyz="0 0 0" rpy="0 1.570796 0"/>
      <geometry>
        <cylinder radius="0.05" length="0.04"/>
      </geometry>
    </collision>
  </link>

  <joint name="right_rear_wheel" type="continuous">
    <parent link="base_link"/>
    <child link="vehicle wheel(3)"/>
    <axis xyz="1 0 0"/>
    <limit effort="1e+08" velocity="29.8"/>
    <origin xyz="-0.162 -0.15 0.05" rpy="0 0 1.5708"/>
  </joint>
  <link name="vehicle wheel(3)">
    <visual>
      <origin xyz="0 0 0" rpy="0 1.570796 0"/>
      <geometry>
        <cylinder radius="0.05" length="0.04"/>
      </geometry>
    </visual>
    <collision>
      <origin xyz="0 0 0" rpy="0 1.570796 0"/>
      <geometry>
        <cylinder radius="0.05" length="0.04"/>
      </geometry>
    </collision>
  </link>
  
  
  <joint name="left_front_wheel" type="continuous">
    <parent link="base_link"/>
    <child link="vehicle wheel(0)"/>
    <axis xyz="-1 0 0"/>
    <limit effort="1e+08" velocity="29.8"/>
    <origin xyz="0.162 0.15 0.05" rpy="0 0 -1.5708"/>
  </joint>
  <link name="vehicle wheel(0)">
    <visual>
      <origin xyz="0 0 0" rpy="0 1.570796 0"/>
      <geometry>
        <cylinder radius="0.05" length="0.04"/>
      </geometry>
    </visual>
    <collision>
      <origin xyz="0 0 0" rpy="0 1.570796 0"/>
      <geometry>
        <cylinder radius="0.05" length="0.04"/>
      </geometry>
    </collision>
  </link>
  
  <joint name="left_rear_wheel" type="continuous">
    <parent link="base_link"/>
    <child link="vehicle wheel(2)"/>
    <axis xyz="-1 0 0"/>
    <limit effort="1e+08" velocity="29.8"/>
    <origin xyz="-0.162 0.15 0.05" rpy="0 0 -1.5708"/>
  </joint>
  <link name="vehicle wheel(2)">
    <visual>
      <origin xyz="0 0 0" rpy="0 1.570796 0"/>
      <geometry>
        <cylinder radius="0.05" length="0.04"/>
      </geometry>
    </visual>
    <collision>
      <origin xyz="0 0 0" rpy="0 1.570796 0"/>
      <geometry>
        <cylinder radius="0.05" length="0.04"/>
      </geometry>
    </collision>
  </link>

  <link name="lidar">
  </link>
  <joint name="base_link_lidar_joint" type="fixed">
    <parent link="base_link"/>
    <child link="lidar"/>
    <origin xyz="0.08 0 0.36" rpy="0 0 0"/>
  </joint>
</robot>
