#VRML_SIM R2023a utf8

EXTERNPROTO "https://raw.githubusercontent.com/cyberbotics/webots/R2023a/projects/objects/floors/protos/Floor.proto"
EXTERNPROTO "https://raw.githubusercontent.com/cyberbotics/webots/R2023a/projects/objects/backgrounds/protos/TexturedBackgroundLight.proto"
EXTERNPROTO "https://raw.githubusercontent.com/cyberbotics/webots/R2023a/projects/appearances/protos/Parquetry.proto"
EXTERNPROTO "https://raw.githubusercontent.com/cyberbotics/webots/R2023a/projects/objects/apartment_structure/protos/Wall.proto"
EXTERNPROTO "https://raw.githubusercontent.com/cyberbotics/webots/R2023a/projects/appearances/protos/Roughcast.proto"
EXTERNPROTO "https://raw.githubusercontent.com/cyberbotics/webots/R2023a/projects/humans/pedestrian/protos/Pedestrian.proto"

WorldInfo {
}
Viewpoint {
  orientation -0.6065685185191103 0.5554657350789404 0.5687991293020271 2.1102521540776267
  position 11.761924437515106 1.3545918200864728 12.057686313140628
}
Floor {
  size 100 100
  appearance Parquetry {
    type "light strip"
    textureTransform TextureTransform {
      scale 0.4 0.4
    }
  }
}
TexturedBackgroundLight {
  texture "noon_cloudy_empty"
  luminosity 3
  castShadows FALSE
}
Wall {
  translation 10 4 4.9738e-14
  size 20 0.2 3
  appearance DEF wall_color Roughcast {
    textureTransform TextureTransform {
      scale 100 100
    }
  }
}
Wall {
  translation 23.9 12 -1.42109e-14
  name "wall(2)"
  size 0.2 24 3
  appearance DEF wall_color Roughcast {
    textureTransform TextureTransform {
      scale 100 100
    }
  }
}
Wall {
  translation 0 2 -1.42109e-14
  name "wall(1)"
  size 0.2 4.2 3
  appearance DEF wall_color Roughcast {
    textureTransform TextureTransform {
      scale 100 100
    }
  }
}
Wall {
  translation 12 0 1.42109e-14
  name "wall(3)"
  size 24 0.2 3
  appearance DEF wall_color Roughcast {
    textureTransform TextureTransform {
      scale 100 100
    }
  }
}
Wall {
  translation 19.9 14 0
  name "wall(4)"
  size 0.2 20 3
  appearance DEF wall_color Roughcast {
    textureTransform TextureTransform {
      scale 100 100
    }
  }
}
DEF p1 Pedestrian {
  translation 20.5 8 1.47
  rotation 0 0 1 -1.5707953071795862
  name "pedestrian(2)"
  controllerArgs [
    "--range=20.5,8,20.5, 23.5, 5, 11"
  ]
  shirtColor 0.666667 0.333333 1
  enableBoundingObject TRUE
}
DEF p2 Pedestrian {
  translation 20.5 11 1.47
  rotation 0 0 1 -1.5707953071795862
  name "pedestrian(3)"
  controllerArgs [
    "--range=20.5,11,20.5, 23.5, 5, 11"
  ]
  shirtColor 0.176471 0.101961 1
  enableBoundingObject TRUE
}
DEF p0 Pedestrian {
  translation 20.5 5 1.57
  rotation 0 0 -1 -5.307179586466759e-06
  name "pedestrian(1)"
  controllerArgs [
    "--range=20.5,5,20.5, 23.5, 5, 11"
  ]
  shirtColor 0.666667 0 0
  enableBoundingObject TRUE
}
DEF supervisor_node Robot {
  controller "<extern>"
  supervisor TRUE
}
Robot {
  translation 12 2 0
  children [
    GPS {
    }
    InertialUnit {
      name "inertial_unit"
    }
    TouchSensor {
      boundingObject Transform {
        translation 0 0 0.1
        children [
          Box {
            size 0.25 0.3 0.18
          }
        ]
      }
    }
    DEF MAIN_BODY Transform {
      translation 0 0 0.023
      children [
        Shape {
          appearance PBRAppearance {
            baseColorMap ImageTexture {
              url [
                "https://raw.githubusercontent.com/cyberbotics/webots/R2023a/projects/appearances/protos/textures/matte_car_paint/matte_car_paint_base_color.jpg"
              ]
              filtering 5
            }
            roughnessMap ImageTexture {
              url [
                "https://raw.githubusercontent.com/cyberbotics/webots/R2023a/projects/appearances/protos/textures/glossy_car_paint/glossy_car_paint_roughness.jpg"
              ]
              filtering 5
            }
            metalness 0
            normalMap ImageTexture {
              url [
                "https://raw.githubusercontent.com/cyberbotics/webots/R2023a/projects/appearances/protos/textures/glossy_car_paint/glossy_car_paint_normal.jpg"
              ]
              filtering 5
            }
            normalMapFactor 0.5
            textureTransform TextureTransform {
              scale 10 10
            }
          }
          geometry Mesh {
            url [
              "https://raw.githubusercontent.com/cyberbotics/webots/R2023a/projects/robots/husarion/rosbot/protos/meshes/box.obj"
            ]
          }
        }
      ]
    }
    DEF PORTS Transform {
      translation 0 0 0.023
      children [
        Shape {
          appearance PBRAppearance {
            baseColor 0 0 0
            baseColorMap ImageTexture {
              url [
                "https://raw.githubusercontent.com/cyberbotics/webots/R2023a/projects/appearances/protos/textures/matte_car_paint/matte_car_paint_base_color.jpg"
              ]
              filtering 5
            }
            roughnessMap ImageTexture {
              url [
                "https://raw.githubusercontent.com/cyberbotics/webots/R2023a/projects/appearances/protos/textures/matte_car_paint/matte_car_paint_roughness.jpg"
              ]
              filtering 5
            }
            metalness 0
            normalMapFactor 0.5
            textureTransform TextureTransform {
              scale 10 10
            }
          }
          geometry Mesh {
            url [
              "https://raw.githubusercontent.com/cyberbotics/webots/R2023a/projects/robots/husarion/rosbot/protos/meshes/black_ports.obj"
            ]
          }
        }
      ]
    }
    DEF METALLIC_CONNECTIONS Transform {
      translation 0 0 0.023
      children [
        Shape {
          appearance PBRAppearance {
            baseColor 0.7 0.7 0.7
            baseColorMap ImageTexture {
              url [
                "https://raw.githubusercontent.com/cyberbotics/webots/R2023a/projects/appearances/protos/textures/brushed_aluminium/brushed_aluminium_base_color.jpg"
              ]
            }
            roughnessMap ImageTexture {
              url [
                "https://raw.githubusercontent.com/cyberbotics/webots/R2023a/projects/appearances/protos/textures/brushed_aluminium/brushed_aluminium_roughness.jpg"
              ]
            }
            normalMap ImageTexture {
              url [
                "https://raw.githubusercontent.com/cyberbotics/webots/R2023a/projects/appearances/protos/textures/brushed_aluminium/brushed_aluminium_normal.jpg"
              ]
            }
          }
          geometry Mesh {
            url [
              "https://raw.githubusercontent.com/cyberbotics/webots/R2023a/projects/robots/husarion/rosbot/protos/meshes/metallic_connections.obj"
            ]
          }
        }
      ]
    }
    DEF ANTENNA Transform {
      translation -0.099 0.05 0.1
      rotation 0 1 0 -0.785395307179586
      children [
        Shape {
          appearance PBRAppearance {
            baseColor 0 0 0
            baseColorMap ImageTexture {
              url [
                "https://raw.githubusercontent.com/cyberbotics/webots/R2023a/projects/appearances/protos/textures/matte_car_paint/matte_car_paint_base_color.jpg"
              ]
              filtering 5
            }
            roughnessMap ImageTexture {
              url [
                "https://raw.githubusercontent.com/cyberbotics/webots/R2023a/projects/appearances/protos/textures/matte_car_paint/matte_car_paint_roughness.jpg"
              ]
              filtering 5
            }
            metalness 0
            normalMapFactor 0.5
            textureTransform TextureTransform {
              scale 10 10
            }
          }
          geometry Cylinder {
            height 0.02
            radius 0.005
          }
        }
        Transform {
          translation 0.023 0 0.032
          rotation 0 1 0 0.785398
          children [
            Shape {
              appearance PBRAppearance {
                baseColor 0 0 0
                baseColorMap ImageTexture {
                  url [
                    "https://raw.githubusercontent.com/cyberbotics/webots/R2023a/projects/appearances/protos/textures/matte_car_paint/matte_car_paint_base_color.jpg"
                  ]
                  filtering 5
                }
                roughnessMap ImageTexture {
                  url [
                    "https://raw.githubusercontent.com/cyberbotics/webots/R2023a/projects/appearances/protos/textures/matte_car_paint/matte_car_paint_roughness.jpg"
                  ]
                  filtering 5
                }
                metalness 0
                normalMapFactor 0.5
                textureTransform TextureTransform {
                  scale 10 10
                }
              }
              geometry Capsule {
                bottom FALSE
                height 0.07
                radius 0.004
              }
            }
          ]
        }
      ]
    }
    DEF LIDAR_CABLE Transform {
      translation -0.034 0 0.1004
      rotation 0 -1 0 -0.261795307179586
      children [
        Shape {
          appearance PBRAppearance {
            baseColor 0 0 0
            baseColorMap ImageTexture {
              url [
                "https://raw.githubusercontent.com/cyberbotics/webots/R2023a/projects/appearances/protos/textures/matte_car_paint/matte_car_paint_base_color.jpg"
              ]
              filtering 5
            }
            roughnessMap ImageTexture {
              url [
                "https://raw.githubusercontent.com/cyberbotics/webots/R2023a/projects/appearances/protos/textures/matte_car_paint/matte_car_paint_roughness.jpg"
              ]
              filtering 5
            }
            metalness 0
            normalMapFactor 0.5
            textureTransform TextureTransform {
              scale 10 10
            }
          }
          geometry Capsule {
            height 0.01
            radius 0.003
          }
        }
      ]
    }
    DEF SCREWS Group {
      children [
        DEF SCREW1 Transform {
          translation 0.07 0.068 0.091
          rotation 1 0 0 3.14159
          children [
            DEF BLACK_SCREW_SHAPE Shape {
              appearance PBRAppearance {
                baseColor 0 0 0
                baseColorMap ImageTexture {
                  url [
                    "https://raw.githubusercontent.com/cyberbotics/webots/R2023a/projects/appearances/protos/textures/matte_car_paint/matte_car_paint_base_color.jpg"
                  ]
                  filtering 5
                }
                roughnessMap ImageTexture {
                  url [
                    "https://raw.githubusercontent.com/cyberbotics/webots/R2023a/projects/appearances/protos/textures/glossy_car_paint/glossy_car_paint_roughness.jpg"
                  ]
                  filtering 5
                }
                metalness 0
                normalMap ImageTexture {
                  url [
                    "https://raw.githubusercontent.com/cyberbotics/webots/R2023a/projects/appearances/protos/textures/glossy_car_paint/glossy_car_paint_normal.jpg"
                  ]
                  filtering 5
                }
                normalMapFactor 0.5
                textureTransform TextureTransform {
                  scale 10 10
                }
              }
              geometry Mesh {
                url [
                  "https://raw.githubusercontent.com/cyberbotics/webots/R2023a/projects/robots/husarion/rosbot/protos/meshes/screw.obj"
                ]
              }
            }
          ]
        }
        DEF SCREW2 Transform {
          translation 0 0.068 0.091
          rotation 1 0 0 3.14159
          children [
            USE BLACK_SCREW_SHAPE
          ]
        }
        DEF SCREW3 Transform {
          translation -0.07 0.068 0.091
          rotation 1 0 0 3.14159
          children [
            USE BLACK_SCREW_SHAPE
          ]
        }
        DEF SCREW4 Transform {
          translation 0.07 -0.068 0.091
          rotation 1 0 0 3.14159
          children [
            USE BLACK_SCREW_SHAPE
          ]
        }
        DEF SCREW5 Transform {
          translation 0 -0.068 0.091
          rotation 1 0 0 3.14159
          children [
            USE BLACK_SCREW_SHAPE
          ]
        }
        DEF SCREW6 Transform {
          translation -0.07 -0.068 0.091
          rotation 1 0 0 3.14159
          children [
            USE BLACK_SCREW_SHAPE
          ]
        }
        DEF SCREW7 Transform {
          translation 0.089 -0.068 0.055
          rotation 0.577349935856137 0.5773509358560258 -0.577349935856137 -2.094395307179586
          children [
            USE BLACK_SCREW_SHAPE
          ]
        }
        DEF SCREW8 Transform {
          translation 0.089 -0.031 0.055
          rotation 0.577349935856137 0.5773509358560258 -0.577349935856137 -2.094395307179586
          children [
            USE BLACK_SCREW_SHAPE
          ]
        }
        DEF SCREW9 Transform {
          translation 0.089 0.068 0.055
          rotation 0.577349935856137 0.5773509358560258 -0.577349935856137 -2.094395307179586
          children [
            USE BLACK_SCREW_SHAPE
          ]
        }
        DEF SCREW10 Transform {
          translation 0.089 0.031 0.055
          rotation 0.577349935856137 0.5773509358560258 -0.577349935856137 -2.094395307179586
          children [
            USE BLACK_SCREW_SHAPE
          ]
        }
        DEF SCREW11 Transform {
          translation -0.083 0.035 0.0845
          rotation 0.9238797538372345 5.077418647149253e-07 0.38268289803621075 3.14159
          children [
            USE BLACK_SCREW_SHAPE
          ]
        }
        DEF SCREW12 Transform {
          translation -0.083 0.005 0.0845
          rotation 0.9238797538372345 5.077418647149253e-07 0.38268289803621075 3.14159
          children [
            USE BLACK_SCREW_SHAPE
          ]
        }
        DEF SCREW13 Transform {
          translation -0.083 -0.005 0.0845
          rotation 0.9238797538372345 5.077418647149253e-07 0.38268289803621075 3.14159
          children [
            USE BLACK_SCREW_SHAPE
          ]
        }
        DEF SCREW14 Transform {
          translation -0.083 -0.035 0.0845
          rotation 0.9238797538372345 5.077418647149253e-07 0.38268289803621075 3.14159
          children [
            USE BLACK_SCREW_SHAPE
          ]
        }
        DEF SCREW15 Transform {
          translation -0.089 0.0685 0.052
          rotation 0 1 0 1.5708
          children [
            USE BLACK_SCREW_SHAPE
          ]
        }
        DEF SCREW16 Transform {
          translation -0.089 0.0315 0.052
          rotation 0 1 0 1.5708
          children [
            USE BLACK_SCREW_SHAPE
          ]
        }
        DEF SCREW17 Transform {
          translation -0.089 -0.0685 0.052
          rotation 0 1 0 1.5708
          children [
            USE BLACK_SCREW_SHAPE
          ]
        }
        DEF SCREW18 Transform {
          translation -0.089 -0.0315 0.052
          rotation 0 1 0 1.5708
          children [
            USE BLACK_SCREW_SHAPE
          ]
        }
        DEF SCREW19 Transform {
          translation -0.089 -0.036 0.077
          rotation 0 1 0 1.5708
          children [
            USE BLACK_SCREW_SHAPE
          ]
        }
        DEF SCREW20 Transform {
          translation -0.089 -0.069 0.077
          rotation 0 1 0 1.5708
          children [
            USE BLACK_SCREW_SHAPE
          ]
        }
        DEF SCREW21 Transform {
          translation -0.089 0.0065 0.0735
          rotation 0 1 0 1.5708
          children [
            USE BLACK_SCREW_SHAPE
          ]
        }
        DEF SCREW22 Transform {
          translation -0.089 0.0365 0.072
          rotation 0 1 0 1.5708
          children [
            DEF METAL_SCREW_SHAPE Shape {
              appearance PBRAppearance {
                baseColorMap ImageTexture {
                  url [
                    "https://raw.githubusercontent.com/cyberbotics/webots/R2023a/projects/appearances/protos/textures/brushed_aluminium/brushed_aluminium_base_color.jpg"
                  ]
                }
                roughnessMap ImageTexture {
                  url [
                    "https://raw.githubusercontent.com/cyberbotics/webots/R2023a/projects/appearances/protos/textures/brushed_aluminium/brushed_aluminium_roughness.jpg"
                  ]
                }
                normalMap ImageTexture {
                  url [
                    "https://raw.githubusercontent.com/cyberbotics/webots/R2023a/projects/appearances/protos/textures/brushed_aluminium/brushed_aluminium_normal.jpg"
                  ]
                }
              }
              geometry Mesh {
                url [
                  "https://raw.githubusercontent.com/cyberbotics/webots/R2023a/projects/robots/husarion/rosbot/protos/meshes/screw.obj"
                ]
              }
            }
          ]
        }
        DEF SCREW23 Transform {
          translation -0.089 0.0635 0.072
          rotation 0 1 0 1.5708
          children [
            USE METAL_SCREW_SHAPE
          ]
        }
        DEF SCREW24 Transform {
          translation 0.008 0.0665 0.0915
          rotation 0.5773489358556708 0.5773509358554485 -0.5773509358554485 2.0944
          children [
            USE METAL_SCREW_SHAPE
          ]
        }
        DEF SCREW25 Transform {
          translation -0.008 0.0665 0.0915
          rotation 0.5773489358556708 0.5773509358554485 -0.5773509358554485 2.0944
          children [
            USE METAL_SCREW_SHAPE
          ]
        }
        DEF SCREW26 Transform {
          translation 0.008 -0.0665 0.0915
          rotation -1 0 0 1.5708
          children [
            USE METAL_SCREW_SHAPE
          ]
        }
        DEF SCREW27 Transform {
          translation -0.008 -0.0665 0.0915
          rotation -1 0 0 1.5708
          children [
            USE METAL_SCREW_SHAPE
          ]
        }
      ]
    }
    DEF INTERIOR Transform {
      translation 0 0 0.061
      children [
        Shape {
          appearance PBRAppearance {
            baseColor 0 0 0
            baseColorMap ImageTexture {
              url [
                "https://raw.githubusercontent.com/cyberbotics/webots/R2023a/projects/appearances/protos/textures/matte_car_paint/matte_car_paint_base_color.jpg"
              ]
              filtering 5
            }
            roughnessMap ImageTexture {
              url [
                "https://raw.githubusercontent.com/cyberbotics/webots/R2023a/projects/appearances/protos/textures/matte_car_paint/matte_car_paint_roughness.jpg"
              ]
              filtering 5
            }
            metalness 0
            normalMapFactor 0.5
            textureTransform TextureTransform {
              scale 10 10
            }
          }
          geometry Box {
            size 0.15 0.14 0.07
          }
        }
      ]
    }
    Solid {
      children [
        Transform {
          translation 0 0 0.098
          children [
            Shape {
              appearance PBRAppearance {
                baseColor 0.8 0 0
                baseColorMap ImageTexture {
                  url [
                    "https://raw.githubusercontent.com/cyberbotics/webots/R2023a/projects/appearances/protos/textures/matte_car_paint/matte_car_paint_base_color.jpg"
                  ]
                  filtering 5
                }
                roughnessMap ImageTexture {
                  url [
                    "https://raw.githubusercontent.com/cyberbotics/webots/R2023a/projects/appearances/protos/textures/glossy_car_paint/glossy_car_paint_roughness.jpg"
                  ]
                  filtering 5
                }
                metalness 0
                normalMap ImageTexture {
                  url [
                    "https://raw.githubusercontent.com/cyberbotics/webots/R2023a/projects/appearances/protos/textures/glossy_car_paint/glossy_car_paint_normal.jpg"
                  ]
                  filtering 5
                }
                normalMapFactor 0.5
                textureTransform TextureTransform {
                  scale 10 10
                }
              }
              geometry Mesh {
                url [
                  "https://raw.githubusercontent.com/cyberbotics/webots/R2023a/projects/robots/husarion/rosbot/protos/meshes/upper.obj"
                ]
              }
            }
          ]
        }
      ]
      name "top body"
    }
    DEF FL_WHEEL_AXIS Transform {
      translation 0.053 0.092 0.041
      rotation 1 0 0 -1.5707953071795862
      children [
        Shape {
          appearance PBRAppearance {
            baseColor 0.11 0.11 0.11
            baseColorMap ImageTexture {
              url [
                "https://raw.githubusercontent.com/cyberbotics/webots/R2023a/projects/appearances/protos/textures/matte_car_paint/matte_car_paint_base_color.jpg"
              ]
              filtering 5
            }
            roughnessMap ImageTexture {
              url [
                "https://raw.githubusercontent.com/cyberbotics/webots/R2023a/projects/appearances/protos/textures/glossy_car_paint/glossy_car_paint_roughness.jpg"
              ]
              filtering 5
            }
            metalness 0
            normalMap ImageTexture {
              url [
                "https://raw.githubusercontent.com/cyberbotics/webots/R2023a/projects/appearances/protos/textures/glossy_car_paint/glossy_car_paint_normal.jpg"
              ]
              filtering 5
            }
            normalMapFactor 0.5
            textureTransform TextureTransform {
              scale 10 10
            }
          }
          geometry Cylinder {
            height 0.037
            radius 0.005
          }
        }
      ]
    }
    DEF FR_WHEEL_AXIS Transform {
      translation 0.053 -0.092 0.041
      rotation 1 0 0 -1.5707953071795862
      children [
        Shape {
          appearance PBRAppearance {
            baseColor 0.11 0.11 0.11
            baseColorMap ImageTexture {
              url [
                "https://raw.githubusercontent.com/cyberbotics/webots/R2023a/projects/appearances/protos/textures/matte_car_paint/matte_car_paint_base_color.jpg"
              ]
              filtering 5
            }
            roughnessMap ImageTexture {
              url [
                "https://raw.githubusercontent.com/cyberbotics/webots/R2023a/projects/appearances/protos/textures/glossy_car_paint/glossy_car_paint_roughness.jpg"
              ]
              filtering 5
            }
            metalness 0
            normalMap ImageTexture {
              url [
                "https://raw.githubusercontent.com/cyberbotics/webots/R2023a/projects/appearances/protos/textures/glossy_car_paint/glossy_car_paint_normal.jpg"
              ]
              filtering 5
            }
            normalMapFactor 0.5
            textureTransform TextureTransform {
              scale 10 10
            }
          }
          geometry Cylinder {
            height 0.037
            radius 0.005
          }
        }
      ]
    }
    DEF RL_WHEEL_AXIS Transform {
      translation -0.054 0.092 0.041
      rotation 1 0 0 -1.5707953071795862
      children [
        Shape {
          appearance PBRAppearance {
            baseColor 0.11 0.11 0.11
            baseColorMap ImageTexture {
              url [
                "https://raw.githubusercontent.com/cyberbotics/webots/R2023a/projects/appearances/protos/textures/matte_car_paint/matte_car_paint_base_color.jpg"
              ]
              filtering 5
            }
            roughnessMap ImageTexture {
              url [
                "https://raw.githubusercontent.com/cyberbotics/webots/R2023a/projects/appearances/protos/textures/glossy_car_paint/glossy_car_paint_roughness.jpg"
              ]
              filtering 5
            }
            metalness 0
            normalMap ImageTexture {
              url [
                "https://raw.githubusercontent.com/cyberbotics/webots/R2023a/projects/appearances/protos/textures/glossy_car_paint/glossy_car_paint_normal.jpg"
              ]
              filtering 5
            }
            normalMapFactor 0.5
            textureTransform TextureTransform {
              scale 10 10
            }
          }
          geometry Cylinder {
            height 0.037
            radius 0.005
          }
        }
      ]
    }
    DEF RR_WHEEL_AXIS Transform {
      translation -0.054 -0.092 0.041
      rotation 1 0 0 -1.5707953071795862
      children [
        Shape {
          appearance PBRAppearance {
            baseColor 0.11 0.11 0.11
            baseColorMap ImageTexture {
              url [
                "https://raw.githubusercontent.com/cyberbotics/webots/R2023a/projects/appearances/protos/textures/matte_car_paint/matte_car_paint_base_color.jpg"
              ]
              filtering 5
            }
            roughnessMap ImageTexture {
              url [
                "https://raw.githubusercontent.com/cyberbotics/webots/R2023a/projects/appearances/protos/textures/glossy_car_paint/glossy_car_paint_roughness.jpg"
              ]
              filtering 5
            }
            metalness 0
            normalMap ImageTexture {
              url [
                "https://raw.githubusercontent.com/cyberbotics/webots/R2023a/projects/appearances/protos/textures/glossy_car_paint/glossy_car_paint_normal.jpg"
              ]
              filtering 5
            }
            normalMapFactor 0.5
            textureTransform TextureTransform {
              scale 10 10
            }
          }
          geometry Cylinder {
            height 0.037
            radius 0.005
          }
        }
      ]
    }
    HingeJoint {
      jointParameters HingeJointParameters {
        axis 0 1 0
        anchor 0.05 0.11 0.043
        dampingConstant 5
        staticFriction 1
      }
      device [
        RotationalMotor {
          name "front left wheel motor"
          maxVelocity 26
          maxTorque 100
        }
        PositionSensor {
          name "front left wheel motor sensor"
        }
      ]
      endPoint Solid {
        translation 0.05 0.11 0.043
        children [
          Transform {
            children [
              DEF RIM_AND_TIRE_SHAPES Group {
                children [
                  DEF RIM_SHAPE Shape {
                    appearance PBRAppearance {
                      baseColorMap ImageTexture {
                        url [
                          "https://raw.githubusercontent.com/cyberbotics/webots/R2023a/projects/appearances/protos/textures/brushed_aluminium/brushed_aluminium_base_color.jpg"
                        ]
                      }
                      roughnessMap ImageTexture {
                        url [
                          "https://raw.githubusercontent.com/cyberbotics/webots/R2023a/projects/appearances/protos/textures/brushed_aluminium/brushed_aluminium_roughness.jpg"
                        ]
                      }
                      normalMap ImageTexture {
                        url [
                          "https://raw.githubusercontent.com/cyberbotics/webots/R2023a/projects/appearances/protos/textures/brushed_aluminium/brushed_aluminium_normal.jpg"
                        ]
                      }
                    }
                    geometry Mesh {
                      url [
                        "https://raw.githubusercontent.com/cyberbotics/webots/R2023a/projects/robots/husarion/rosbot/protos/meshes/wheel_rim.obj"
                      ]
                    }
                  }
                  DEF TIRE_SHAPE Shape {
                    appearance PBRAppearance {
                      baseColorMap ImageTexture {
                        url [
                          "https://raw.githubusercontent.com/cyberbotics/webots/R2023a/projects/appearances/protos/textures/rubber/flat_rubber_base_color.jpg"
                        ]
                      }
                      roughnessMap ImageTexture {
                        url [
                          "https://raw.githubusercontent.com/cyberbotics/webots/R2023a/projects/appearances/protos/textures/rubber/flat_rubber_roughness.jpg"
                        ]
                      }
                      metalness 0
                      normalMap ImageTexture {
                        url [
                          "https://raw.githubusercontent.com/cyberbotics/webots/R2023a/projects/appearances/protos/textures/rubber/flat_rubber_normal.jpg"
                        ]
                      }
                      occlusionMap ImageTexture {
                        url [
                          "https://raw.githubusercontent.com/cyberbotics/webots/R2023a/projects/appearances/protos/textures/rubber/flat_rubber_occlusion.jpg"
                        ]
                      }
                    }
                    geometry Mesh {
                      url [
                        "https://raw.githubusercontent.com/cyberbotics/webots/R2023a/projects/robots/husarion/rosbot/protos/meshes/wheel_tire.obj"
                      ]
                    }
                  }
                ]
              }
            ]
          }
        ]
        name "front left wheel"
        boundingObject DEF LEFT_WHEEL_CYLINDER Transform {
          translation 0 -0.0115 0
          rotation 1 0 0 -1.5708
          children [
            DEF WHEEL_CYLINDER Cylinder {
              height 0.035
              radius 0.043
            }
          ]
        }
        physics DEF WHEEL_PHYSICS Physics {
          density -1
          mass 0.5
        }
      }
    }
    HingeJoint {
      jointParameters HingeJointParameters {
        axis 0 1 0
        anchor 0.05 -0.11 0.043
        dampingConstant 5
        staticFriction 1
      }
      device [
        RotationalMotor {
          name "front right wheel motor"
          maxVelocity 26
          maxTorque 100
        }
        PositionSensor {
          name "front right wheel motor sensor"
        }
      ]
      endPoint Solid {
        translation 0.05 -0.11 0.043
        children [
          Transform {
            rotation 0 0 1 3.141592
            children [
              USE RIM_AND_TIRE_SHAPES
            ]
          }
        ]
        name "front right wheel"
        boundingObject DEF RIGHT_WHEEL_CYLINDER Transform {
          translation 0 0.0115 0
          rotation 1 0 0 -1.5708
          children [
            USE WHEEL_CYLINDER
          ]
        }
        physics USE WHEEL_PHYSICS
      }
    }
    HingeJoint {
      jointParameters HingeJointParameters {
        axis 0 1 0
        anchor -0.055 0.11 0.043
        dampingConstant 5
        staticFriction 1
      }
      device [
        RotationalMotor {
          name "rear left wheel motor"
          maxVelocity 26
          maxTorque 100
        }
        PositionSensor {
          name "rear left wheel motor sensor"
        }
      ]
      endPoint Solid {
        translation -0.055 0.11 0.043
        children [
          Transform {
            children [
              USE RIM_AND_TIRE_SHAPES
            ]
          }
        ]
        name "rear left wheel"
        boundingObject USE LEFT_WHEEL_CYLINDER
        physics USE WHEEL_PHYSICS
      }
    }
    HingeJoint {
      jointParameters HingeJointParameters {
        axis 0 1 0
        anchor -0.055 -0.11 0.043
        dampingConstant 5
        staticFriction 1
      }
      device [
        RotationalMotor {
          name "rear right wheel motor"
          maxVelocity 26
          maxTorque 100
        }
        PositionSensor {
          name "rear right wheel motor sensor"
        }
      ]
      endPoint Solid {
        translation -0.055 -0.11 0.043
        children [
          Transform {
            rotation 0 0 1 3.141592
            children [
              USE RIM_AND_TIRE_SHAPES
            ]
          }
        ]
        name "rear right wheel"
        boundingObject USE RIGHT_WHEEL_CYLINDER
        physics USE WHEEL_PHYSICS
      }
    }
    DEF DISTANCE_SENSORS Transform {
      translation 0 0 0.023
      children [
        Shape {
          appearance PBRAppearance {
            baseColor 0 0 0
            baseColorMap ImageTexture {
              url [
                "https://raw.githubusercontent.com/cyberbotics/webots/R2023a/projects/appearances/protos/textures/matte_car_paint/matte_car_paint_base_color.jpg"
              ]
              filtering 5
            }
            roughnessMap ImageTexture {
              url [
                "https://raw.githubusercontent.com/cyberbotics/webots/R2023a/projects/appearances/protos/textures/matte_car_paint/matte_car_paint_roughness.jpg"
              ]
              filtering 5
            }
            metalness 0
            normalMapFactor 0.5
            textureTransform TextureTransform {
              scale 10 10
            }
          }
          geometry Mesh {
            url [
              "https://raw.githubusercontent.com/cyberbotics/webots/R2023a/projects/robots/husarion/rosbot/protos/meshes/proximity_sensors.obj"
            ]
          }
        }
      ]
    }
    DistanceSensor {
      translation 0.1 0.05 0.053
      rotation 0 0 1 0.13
      name "front left distance sensor"
      lookupTable [
        0 0 0
        1 1 0
        2 2 0
      ]
      type "infra-red"
      redColorSensitivity 0
    }
    DistanceSensor {
      translation 0.1 -0.05 0.053
      rotation 0 0 1 -0.13
      name "front right distance sensor"
      lookupTable [
        0 0 0
        2 2 0
      ]
      type "infra-red"
      redColorSensitivity 0
    }
    DistanceSensor {
      translation -0.1 0.05 0.053
      rotation 0 0 1 3.01
      name "rear left distance sensor"
      lookupTable [
        0 0 0
        2 2 0
      ]
      type "infra-red"
      redColorSensitivity 0
    }
    DistanceSensor {
      translation -0.1 -0.05 0.053
      rotation 0 0 1 3.27
      name "rear right distance sensor"
      lookupTable [
        0 0 0
        2 2 0
      ]
      type "infra-red"
      redColorSensitivity 0
    }
    DEF CAMERA_SLOT Transform {
      translation -0.027 0 0.165
    }
    DEF LIDAR_SLOT Transform {
      translation 0.02 0 0.1
      children [
        Lidar {
          horizontalResolution 800
          fieldOfView 6.2832
          numberOfLayers 1
          maxRange 20
        }
      ]
    }
  ]
  name "base_link"
  boundingObject Group {
    children [
      DEF MAIN_BODY_BOX Transform {
        translation 0 0 0.0612
        children [
          Box {
            size 0.2 0.15 0.077
          }
        ]
      }
      DEF LEFT_SUPPORT_LEG_BOX Transform {
        translation -0.048 0.038 0.133
        children [
          Box {
            size 0.04 0.023 0.065
          }
        ]
      }
      DEF RIGHT_SUPPORT_LEG_BOX Transform {
        translation -0.048 -0.038 0.133
        children [
          Box {
            size 0.04 0.023 0.065
          }
        ]
      }
      DEF SUPPORT_PLATE_BOX Transform {
        translation -0.048 0 0.163
        children [
          Box {
            size 0.04 0.1 0.001
          }
        ]
      }
    ]
  }
  physics Physics {
    density -1
    mass 0.45
  }
  supervisor TRUE
}
